<?xml version="1.0"?>
<sdf version="1.6">
  <world name="default">
    <physics name="default_physics" default="0" type="ode">
      <max_step_size>0.001</max_step_size>
      <real_time_factor>1</real_time_factor>
      <real_time_update_rate>1000</real_time_update_rate>
      <ode>
        <solver>
          <type>quick</type>
          <iters>50</iters>
          <sor>1.0</sor> <!-- Important, see issue #2209 -->
          <use_dynamic_moi_rescaling>false</use_dynamic_moi_rescaling>
        </solver>
      </ode>
    </physics>
    <include>
      <uri>model://ground_plane</uri>
    </include>
    <include>
      <uri>model://sun</uri>
    </include>
    <model name="robotiq_ft300">
      <link name="ft300_sensor">
        <pose>0 0 0 0 0 0</pose>
        <inertial>
          <inertia>
            <ixx>262 / 1000000</ixx>
            <ixy>0<ixy>
            <ixz>1 / 1000000<ixz>
            <iyy>265 / 1000000<iyy>
            <iyx>0<iyx>
            <iyz>1 / 1000000<iyz>
            <izz>219 / 1000000<izz>
            <izx>-1 / 1000000<izx>
            <izy>1 / 1000000<izy>
          </inertia>
          <mass>0.300000</mass>
        </inertial>
        <visual name="visual_sphere">
          <geometry>
            <sphere>
              <radius>0.100000</radius>
            </sphere>
          </geometry>
        </visual>
        <visual name="visual_cylinder">
          <pose>0 0 -0.75 0 0 0</pose>
          <geometry>
            <cylinder>
              <radius>0.0100000</radius>
              <length>1.5</length>
            </cylinder>
          </geometry>
        </visual>
        <collision name="collision_sphere">
          <max_contacts>250</max_contacts>
          <geometry>
            <sphere>
              <radius>0.100000</radius>
            </sphere>
          </geometry>
        </collision>
      </link>
      <joint name="joint_01" type="revolute">
        <parent>world</parent>
        <child>ft300_sensor</child>s
        <pose>0 0 -1.5 0 0 0</pose>
        <axis>
          <limit>
            <lower>-1.5</lower>
            <upper>1.5</upper>
          </limit>
          <dynamics>
            <damping>0.000000</damping>
            <friction>0.000000</friction>
          </dynamics>
          <xyz>1.000000 0.000000 0.000000</xyz>
        </axis>
        <sensor name="robotiq_ft300" type="force_torque">
          <frame>child</frame>
          <measure_direction>child_to_parent</measure_direction>
          <update_rate>30</update_rate>
        </sensor>
      </joint>
    </model>
  </world>
</sdf>